
local _ = {name = "air", param1 = 0}
local T = {name = "ethereal:banana_trunk", param1 = 255}
local L = {name = "ethereal:bananaleaves", param1 = 255}
local l = {name = "ethereal:bananaleaves", param1 = 180}
local B = {name = "ethereal:banana", param1 = 255}
local b = {name = "ethereal:banana", param1 = 070}

ethereal.bananatree = {

	size = {x = 7, y = 8, z = 7},

	yslice_prob = {
		{ypos = 0, prob = 127},
	},

	data = {

	_,_,_,_,_,_,_,
	_,_,_,_,_,_,_,
	_,_,_,_,_,_,_,
	_,_,_,_,_,_,_,
	_,_,_,_,_,_,_,
	_,_,_,_,_,_,_,
	_,_,_,l,_,_,_,
	_,_,_,L,_,_,_,

	_,_,_,_,_,_,_,
	_,_,_,_,_,_,_,
	_,_,_,_,_,_,_,
	_,_,_,_,_,_,_,
	_,_,_,b,_,_,_,
	_,_,_,B,_,_,_,
	_,_,_,L,_,_,_,
	_,_,_,_,_,_,_,

	_,_,_,_,_,_,_,
	_,_,_,_,_,_,_,
	_,_,_,_,_,_,_,
	_,_,_,_,_,_,_,
	_,_,b,T,b,_,_,
	_,_,B,L,B,_,_,
	_,L,L,L,L,L,_,
	L,l,_,L,_,l,L,

	_,_,_,T,_,_,_,
	_,_,_,T,_,_,_,
	_,_,_,T,_,_,_,
	_,_,_,T,_,_,_,
	_,_,_,b,_,_,_,
	_,_,_,B,_,_,_,
	_,_,_,L,_,_,_,
	_,_,_,_,_,_,_,

	_,_,_,_,_,_,_,
	_,_,_,_,_,_,_,
	_,_,_,_,_,_,_,
	_,_,_,_,_,_,_,
	_,_,_,_,_,_,_,
	_,_,_,_,_,_,_,
	_,_,_,L,_,_,_,
	_,_,_,l,_,_,_,

	_,_,_,_,_,_,_,
	_,_,_,_,_,_,_,
	_,_,_,_,_,_,_,
	_,_,_,_,_,_,_,
	_,_,_,_,_,_,_,
	_,_,_,_,_,_,_,
	_,_,_,_,_,_,_,
	_,_,_,L,_,_,_,

	_,_,_,_,_,_,_,
	_,_,_,_,_,_,_,
	_,_,_,_,_,_,_,
	_,_,_,_,_,_,_,
	_,_,_,_,_,_,_,
	_,_,_,_,_,_,_,
	_,_,_,_,_,_,_,
	_,_,_,_,_,_,_,

	}
}
