
local _ = {name = "air", prob = 0}
local T = {name = "ethereal:redwood_trunk", prob = 255}
local L = {name = "ethereal:redwood_leaves", prob = 255}

ethereal.redwood_tree = {

	size = {x = 15, y = 33, z = 15},

	yslice_prob = {
		{ypos = 0, prob = 127},
		{ypos = 5, prob = 127},
		{ypos = 6, prob = 127},
		{ypos = 7, prob = 127},
		{ypos = 14, prob = 127},
		{ypos = 15, prob = 127},
		{ypos = 16, prob = 127},
	},

	data = {

_,_,_,_,_,_,_,_,_,_,_,_,_,_,_,
_,_,_,_,_,_,_,_,_,_,_,_,_,_,_,
_,_,_,_,_,_,_,_,_,_,_,_,_,_,_,
_,_,_,_,_,_,_,_,_,_,_,_,_,_,_,
_,_,_,_,_,_,_,_,_,_,_,_,_,_,_,
_,_,_,_,_,_,_,_,_,_,_,_,_,_,_,
_,_,_,_,_,_,_,_,_,_,_,_,_,_,_,
_,_,_,_,_,_,_,_,_,_,_,_,_,_,_,
_,_,_,_,_,_,_,_,_,_,_,_,_,_,_,
_,_,_,_,_,_,_,_,_,_,_,_,_,_,_,
_,_,_,_,_,_,_,_,_,_,_,_,_,_,_,
_,_,_,_,_,_,_,_,_,_,_,_,_,_,_,
_,_,_,_,_,_,_,_,_,_,_,_,_,_,_,
_,_,_,_,_,_,_,_,_,_,_,_,_,_,_,
_,_,_,_,_,_,_,_,_,_,_,_,_,_,_,
_,_,_,_,_,_,_,_,_,_,_,_,_,_,_,
_,_,_,_,_,_,_,_,_,_,_,_,_,_,_,
_,_,_,_,_,_,_,_,_,_,_,_,_,_,_,
_,_,_,_,_,L,L,L,L,L,_,_,_,_,_,
_,_,_,_,_,_,L,L,L,_,_,_,_,_,_,
_,_,_,_,_,_,_,_,_,_,_,_,_,_,_,
_,_,_,_,_,_,_,_,_,_,_,_,_,_,_,
_,_,_,_,_,_,_,_,_,_,_,_,_,_,_,
_,_,_,_,_,_,_,_,_,_,_,_,_,_,_,
_,_,_,_,_,_,_,_,_,_,_,_,_,_,_,
_,_,_,_,_,_,_,_,_,_,_,_,_,_,_,
_,_,_,_,_,_,_,_,_,_,_,_,_,_,_,
_,_,_,_,_,_,_,_,_,_,_,_,_,_,_,
_,_,_,_,_,_,_,_,_,_,_,_,_,_,_,
_,_,_,_,_,_,_,_,_,_,_,_,_,_,_,
_,_,_,_,_,_,_,_,_,_,_,_,_,_,_,
_,_,_,_,_,_,_,_,_,_,_,_,_,_,_,
_,_,_,_,_,_,_,_,_,_,_,_,_,_,_,

_,_,_,_,_,_,_,_,_,_,_,_,_,_,_,
_,_,_,_,_,_,_,_,_,_,_,_,_,_,_,
_,_,_,_,_,_,_,_,_,_,_,_,_,_,_,
_,_,_,_,_,_,_,_,_,_,_,_,_,_,_,
_,_,_,_,_,_,_,_,_,_,_,_,_,_,_,
_,_,_,_,_,_,_,_,_,_,_,_,_,_,_,
_,_,_,_,_,_,_,_,_,_,_,_,_,_,_,
_,_,_,_,_,_,_,_,_,_,_,_,_,_,_,
_,_,_,_,_,_,_,_,_,_,_,_,_,_,_,
_,_,_,_,_,_,_,_,_,_,_,_,_,_,_,
_,_,_,_,_,_,_,_,_,_,_,_,_,_,_,
_,_,_,_,_,_,_,_,_,_,_,_,_,_,_,
_,_,_,_,_,_,_,_,_,_,_,_,_,_,_,
_,_,_,_,_,_,_,_,_,_,_,_,_,_,_,
_,_,_,_,_,_,_,_,_,_,_,_,_,_,_,
_,_,_,_,_,_,_,_,_,_,_,_,_,_,_,
_,_,_,_,_,_,_,_,_,_,_,_,_,_,_,
_,_,_,_,_,L,L,_,L,_,_,_,_,_,_,
_,_,_,_,L,L,L,T,L,L,_,_,_,_,_,
_,_,_,_,_,L,L,L,L,_,_,_,_,_,_,
_,_,_,_,_,_,_,_,_,_,_,_,_,_,_,
_,_,_,_,_,_,_,_,_,_,_,_,_,_,_,
_,_,_,_,_,_,_,_,_,_,_,_,_,_,_,
_,_,_,_,_,_,_,_,L,L,L,_,_,_,_,
_,_,_,_,_,_,_,_,_,_,_,_,_,_,_,
_,_,_,_,_,_,_,_,_,_,_,_,_,_,_,
_,_,_,_,_,_,_,_,_,_,_,_,_,_,_,
_,_,_,_,_,_,_,_,_,_,_,_,_,_,_,
_,_,_,_,_,_,_,_,_,_,_,_,_,_,_,
_,_,_,_,_,_,_,_,_,_,_,_,_,_,_,
_,_,_,_,_,_,_,_,_,_,_,_,_,_,_,
_,_,_,_,_,_,_,_,_,_,_,_,_,_,_,
_,_,_,_,_,_,_,_,_,_,_,_,_,_,_,

_,_,_,_,_,_,_,_,_,_,_,_,_,_,_,
_,_,_,_,_,_,_,_,_,_,_,_,_,_,_,
_,_,_,_,_,_,_,_,_,_,_,_,_,_,_,
_,_,_,_,_,_,_,_,_,_,_,_,_,_,_,
_,_,_,_,_,_,_,_,_,_,_,_,_,_,_,
_,_,_,_,_,_,_,_,_,_,_,_,_,_,_,
_,_,_,_,_,_,_,_,_,_,_,_,_,_,_,
_,_,_,_,_,_,_,_,_,_,_,_,_,_,_,
_,_,_,_,_,_,_,_,_,_,_,_,_,_,_,
_,_,_,_,_,_,_,_,_,_,_,_,_,_,_,
_,_,_,_,_,_,_,_,_,_,_,_,_,_,_,
_,_,_,_,_,_,_,_,_,_,_,_,_,_,_,
_,_,_,_,_,_,_,_,_,_,_,_,_,_,_,
_,_,_,_,_,_,_,_,_,_,_,_,_,_,_,
_,_,_,_,_,_,_,_,_,_,_,_,_,_,_,
_,_,_,_,_,_,_,_,_,_,_,_,_,_,_,
_,_,_,_,_,_,_,_,_,_,_,_,_,_,_,
_,_,_,_,_,L,L,T,L,L,_,_,_,_,_,
_,_,_,_,L,L,L,T,L,L,_,_,_,_,_,
_,_,_,_,_,L,L,L,L,_,_,_,_,_,_,
_,_,_,_,_,_,_,_,_,_,_,_,_,_,_,
_,_,_,_,_,_,_,_,_,_,_,_,_,_,_,
_,_,_,_,_,_,_,_,_,_,_,_,_,_,_,
_,_,_,_,_,_,_,L,L,L,L,L,_,_,_,
_,_,_,_,_,_,_,_,L,L,L,_,_,_,_,
_,_,_,_,_,_,_,_,_,_,_,_,_,_,_,
_,_,_,_,_,_,_,_,_,_,_,_,_,_,_,
_,_,_,_,_,_,_,_,_,_,_,_,_,_,_,
_,_,_,_,_,_,_,_,_,_,_,_,_,_,_,
_,_,_,_,_,_,_,_,_,_,_,_,_,_,_,
_,_,_,_,_,_,_,_,_,_,_,_,_,_,_,
_,_,_,_,_,_,_,_,_,_,_,_,_,_,_,
_,_,_,_,_,_,_,_,_,_,_,_,_,_,_,

_,_,_,_,_,_,_,_,_,_,_,_,_,_,_,
_,_,_,_,_,_,_,_,_,_,_,_,_,_,_,
_,_,_,_,_,_,_,_,_,_,_,_,_,_,_,
_,_,_,_,_,_,_,_,_,_,_,_,_,_,_,
_,_,_,_,_,_,_,_,_,_,_,_,_,_,_,
_,_,_,_,_,_,_,_,_,_,_,_,_,_,_,
_,_,_,_,_,_,_,_,_,_,_,_,_,_,_,
_,_,_,_,_,_,_,_,_,_,_,_,_,_,_,
_,_,_,_,_,_,_,_,_,_,_,_,_,_,_,
_,_,_,_,_,_,_,_,_,_,_,_,_,_,_,
_,_,_,_,_,_,_,_,_,_,_,_,_,_,_,
_,_,_,_,_,_,_,_,_,_,_,_,_,_,_,
_,_,_,_,_,_,_,_,_,_,_,_,_,_,_,
_,_,_,_,_,_,_,_,_,_,_,_,_,_,_,
_,_,_,_,_,_,_,_,_,_,_,_,_,_,_,
_,_,_,_,_,_,_,_,_,_,_,_,_,_,_,
_,_,_,_,_,_,_,_,_,_,_,_,_,_,_,
_,_,_,_,_,L,L,T,L,L,_,_,_,_,_,
_,_,_,_,_,L,L,L,L,_,_,_,_,_,_,
_,_,_,_,_,_,_,L,_,_,_,_,_,_,_,
_,_,_,_,_,_,_,_,_,_,_,_,_,_,_,
_,_,_,_,_,_,_,_,_,_,_,_,_,_,_,
_,_,_,_,_,_,_,_,_,_,_,_,_,_,_,
_,_,_,_,_,_,_,L,L,T,L,L,_,_,_,
_,_,_,_,_,_,_,_,L,L,L,_,_,_,_,
_,_,_,_,_,_,_,_,_,_,_,_,_,_,_,
_,_,_,_,L,L,L,L,_,_,_,_,_,_,_,
_,_,_,_,_,_,_,_,_,_,_,_,_,_,_,
_,_,_,_,_,_,_,_,_,_,_,_,_,_,_,
_,_,_,_,_,_,L,L,_,_,_,_,_,_,_,
_,_,_,_,_,_,_,_,_,_,_,_,_,_,_,
_,_,_,_,_,_,_,_,_,_,_,_,_,_,_,
_,_,_,_,_,_,_,_,_,_,_,_,_,_,_,

_,_,_,_,_,T,T,T,T,T,_,_,_,_,_,
_,_,_,_,_,_,T,T,_,_,_,_,_,_,_,
_,_,_,_,_,_,_,_,_,_,_,_,_,_,_,
_,_,_,_,_,_,_,_,_,_,_,_,_,_,_,
_,_,_,_,_,_,_,_,_,_,_,_,_,_,_,
_,_,_,_,_,_,_,_,_,_,_,_,_,_,_,
_,_,_,_,_,_,_,_,_,_,_,_,_,_,_,
_,_,_,_,_,_,_,_,_,_,_,_,_,_,_,
_,_,_,_,_,_,_,_,_,_,_,_,_,_,_,
_,_,_,_,_,_,_,_,_,_,_,_,_,_,_,
_,_,_,_,_,_,_,_,_,_,_,_,_,_,_,
_,_,_,_,_,_,_,_,_,_,_,_,_,_,_,
_,_,_,_,_,_,_,_,_,_,_,_,_,_,_,
_,_,_,_,_,_,_,_,_,_,_,_,_,_,_,
_,_,_,_,_,_,_,_,_,_,_,_,_,_,_,
_,_,_,_,_,_,_,_,_,_,_,_,_,_,_,
_,_,_,_,_,_,_,_,_,_,_,_,_,_,_,
_,_,_,_,_,_,L,T,L,L,_,_,_,_,_,
_,_,_,_,_,_,L,L,_,_,_,_,_,_,_,
_,_,_,_,_,_,_,_,_,_,_,_,_,_,_,
_,_,_,_,_,_,_,_,_,_,_,_,_,_,_,
_,_,_,_,_,_,_,_,_,_,_,_,_,_,_,
_,_,_,_,_,_,_,_,_,T,_,_,_,_,_,
_,_,_,_,_,_,_,L,L,T,L,L,_,_,_,
_,_,_,_,_,_,_,_,L,L,L,_,_,_,_,
_,_,_,_,_,_,_,_,_,_,_,_,_,_,_,
_,_,_,L,L,L,L,L,L,_,_,_,_,_,_,
_,_,_,_,_,L,L,_,_,_,_,_,_,_,_,
_,_,_,_,_,_,_,_,_,_,_,_,_,_,_,
_,_,_,_,_,_,L,L,L,L,_,_,_,_,_,
_,_,_,_,_,_,L,L,L,_,_,_,_,_,_,
_,_,_,_,_,_,_,_,_,_,_,_,_,_,_,
_,_,_,_,_,_,_,_,_,_,_,_,_,_,_,

_,_,_,_,_,T,T,T,T,T,_,_,_,_,_,
_,_,_,_,_,T,T,T,T,T,_,_,_,_,_,
_,_,_,_,_,_,T,T,T,_,_,_,_,_,_,
_,_,_,_,_,_,T,T,T,_,_,_,_,_,_,
_,_,_,_,_,_,T,T,T,_,_,_,_,_,_,
_,_,_,_,_,_,T,T,T,_,_,_,_,_,_,
_,_,_,_,_,_,T,T,T,_,_,_,_,_,_,
_,_,_,_,_,_,T,T,T,_,_,_,_,_,_,
_,_,_,_,_,_,T,T,T,_,_,_,_,_,_,
_,_,_,_,_,_,_,T,_,_,_,_,_,_,_,
_,_,_,_,_,_,_,T,_,_,_,_,_,_,_,
_,_,_,_,_,_,_,T,_,_,_,_,_,_,_,
_,_,_,_,_,_,_,_,_,_,_,_,_,_,_,
_,_,_,_,_,_,_,_,_,_,_,_,_,_,_,
_,_,_,_,_,_,_,_,_,_,_,_,_,_,_,
_,_,_,_,_,_,_,_,_,_,_,_,_,_,_,
_,_,_,_,_,_,_,_,_,_,_,_,_,_,_,
_,_,_,_,_,_,_,T,_,_,_,_,_,_,_,
_,_,_,_,_,_,_,_,_,_,_,_,_,_,_,
_,_,_,_,_,_,_,_,_,_,_,_,_,_,_,
_,_,_,_,_,_,_,_,_,_,_,_,_,_,_,
_,_,_,_,_,_,_,_,_,_,_,_,_,_,_,
_,_,_,_,_,_,_,_,T,T,_,_,_,_,_,
_,_,_,_,_,_,_,_,L,L,_,L,L,L,L,
_,_,_,_,_,_,_,_,_,_,_,_,_,_,_,
_,_,_,_,_,_,_,_,_,_,_,_,_,_,_,
_,_,_,L,L,T,T,L,L,_,_,_,_,_,_,
_,_,_,_,L,L,L,_,_,_,_,_,_,_,_,
_,_,_,_,_,_,_,L,_,_,_,_,_,_,_,
_,_,_,_,L,L,L,L,L,L,_,_,_,_,_,
_,_,_,_,_,L,L,L,L,L,_,_,_,_,_,
_,_,_,_,_,_,L,L,L,_,_,_,_,_,_,
_,_,_,_,_,_,_,_,_,_,_,_,_,_,_,

_,_,_,_,T,T,T,T,T,T,T,_,_,_,_,
_,_,_,_,T,T,T,T,T,T,_,_,_,_,_,
_,_,_,_,_,T,T,T,T,T,_,_,_,_,_,
_,_,_,_,_,T,T,T,T,T,_,_,_,_,_,
_,_,_,_,_,T,T,T,T,T,_,_,_,_,_,
_,_,_,_,_,T,T,T,T,T,_,_,_,_,_,
_,_,_,_,_,T,T,T,T,T,_,_,_,_,_,
_,_,_,_,_,T,T,T,T,T,_,_,_,_,_,
_,_,_,_,_,T,T,T,T,T,_,_,_,_,_,
_,_,_,_,_,_,T,T,T,_,_,_,_,_,_,
_,_,_,_,_,_,T,T,T,_,_,_,_,_,_,
_,_,_,_,_,_,T,T,T,_,_,_,_,_,_,
_,_,_,_,_,_,T,T,T,_,_,_,_,_,_,
_,_,_,_,_,_,T,T,T,_,_,_,_,_,_,
_,_,_,_,_,_,T,T,T,_,_,_,_,_,_,
_,_,_,_,_,_,T,T,T,_,_,_,_,_,_,
_,_,_,_,_,_,T,T,T,_,_,_,_,_,_,
_,_,_,_,_,_,T,T,T,_,_,_,_,_,_,
_,_,_,_,_,_,T,T,T,_,_,_,_,_,_,
_,_,_,_,_,_,T,T,T,_,_,_,_,_,_,
L,L,L,L,_,_,T,T,T,_,_,_,_,_,_,
_,_,_,_,_,_,T,T,T,_,_,_,_,_,_,
_,_,_,_,_,_,T,T,T,_,_,_,_,_,_,
_,_,_,_,_,_,_,T,_,_,L,L,L,L,L,
_,_,_,_,_,_,_,T,_,_,_,L,L,L,_,
_,_,_,_,_,_,_,T,_,_,_,_,_,_,_,
_,_,_,_,L,L,T,T,_,_,_,_,_,_,_,
_,_,_,_,L,_,_,T,_,_,_,_,_,_,_,
_,_,_,_,_,_,L,T,L,_,_,_,_,_,_,
_,_,_,_,L,L,L,L,L,L,L,_,_,_,_,
_,_,_,_,L,L,L,L,L,L,L,_,_,_,_,
_,_,_,_,_,L,L,L,L,L,_,_,_,_,_,
_,_,_,_,_,_,_,L,_,_,_,_,_,_,_,

_,_,_,_,T,T,T,T,T,T,T,_,_,_,_,
_,_,_,_,T,T,T,T,T,T,T,_,_,_,_,
_,_,_,_,T,T,T,T,T,T,T,_,_,_,_,
_,_,_,_,_,T,T,T,T,T,_,_,_,_,_,
_,_,_,_,_,T,T,T,T,T,_,_,_,_,_,
_,_,_,_,_,T,T,T,T,T,_,_,_,_,_,
_,_,_,_,_,T,T,T,T,T,_,_,_,_,_,
_,_,_,_,_,T,T,T,T,T,_,_,_,_,_,
_,_,_,_,_,T,T,T,T,T,_,_,_,_,_,
_,_,_,_,_,T,T,T,T,T,_,_,_,_,_,
_,_,_,_,_,T,T,T,T,T,_,_,_,_,_,
_,_,_,_,_,_,T,T,T,_,_,_,_,_,_,
_,_,_,_,_,_,T,T,T,_,_,_,_,_,_,
_,_,_,_,_,_,T,T,T,T,T,T,_,_,_,
_,_,_,_,_,_,T,T,T,_,_,L,L,L,L,
_,_,_,_,_,_,T,T,T,_,_,_,L,L,L,
_,_,_,_,_,_,T,T,T,_,_,_,_,_,_,
_,_,_,_,_,_,T,T,T,_,_,_,_,_,_,
_,_,_,_,_,_,T,T,T,_,_,_,_,_,_,
_,_,_,T,T,T,T,T,T,_,_,_,_,_,_,
L,L,L,L,L,_,T,T,T,_,_,_,_,_,_,
L,L,L,L,_,_,T,T,T,_,_,_,_,_,_,
_,_,_,_,_,_,T,T,T,T,T,T,_,_,_,
_,_,_,_,_,_,T,T,T,_,L,T,T,T,L,
_,_,_,_,_,_,T,T,T,_,_,L,L,L,L,
_,_,L,L,L,L,T,T,T,_,_,_,_,_,_,
_,_,_,_,_,_,T,T,T,_,_,_,_,_,_,
_,_,_,_,_,_,T,T,T,_,_,_,_,_,_,
_,_,_,_,_,L,T,T,T,L,_,_,_,_,_,
_,_,_,_,L,L,L,T,L,L,L,_,_,_,_,
_,_,_,_,L,L,L,L,L,L,L,_,_,_,_,
_,_,_,_,_,L,L,L,L,L,_,_,_,_,_,
_,_,_,_,_,_,L,L,L,_,_,_,_,_,_,

_,_,_,_,T,T,T,T,T,T,T,_,_,_,_,
_,_,_,_,T,T,T,T,T,T,T,_,_,_,_,
_,_,_,_,_,T,T,T,T,T,T,_,_,_,_,
_,_,_,_,_,T,T,T,T,T,_,_,_,_,_,
_,_,_,_,_,T,T,T,T,T,_,_,_,_,_,
_,_,_,_,_,T,T,T,T,T,_,_,_,_,_,
_,_,_,_,_,T,T,T,T,T,_,_,_,_,_,
_,_,_,_,_,T,T,T,T,T,_,_,_,_,_,
_,_,_,_,_,T,T,T,T,T,_,_,_,_,_,
_,_,_,_,_,_,T,T,T,_,_,_,_,_,_,
_,_,_,_,_,_,T,T,T,_,_,_,_,_,_,
_,_,_,_,_,_,T,T,T,_,_,_,_,_,_,
_,_,_,_,_,_,T,T,T,_,_,_,_,_,_,
_,_,_,_,_,_,T,T,T,_,_,T,T,_,_,
_,_,_,_,_,_,T,T,T,_,_,L,T,T,L,
_,_,_,_,_,_,T,T,T,_,_,_,L,L,L,
_,_,_,_,_,_,T,T,T,_,_,_,_,_,_,
_,_,_,_,_,_,T,T,T,_,_,_,_,_,_,
_,_,_,_,_,_,T,T,T,_,_,_,_,_,_,
_,_,_,T,_,_,T,T,T,_,_,_,_,_,_,
L,T,T,T,L,_,T,T,T,_,_,_,_,_,_,
L,L,L,L,_,_,T,T,T,_,_,_,_,_,_,
_,_,_,_,_,_,T,T,T,_,_,_,_,_,_,
_,_,_,_,_,_,T,T,_,_,_,L,L,L,L,
_,_,_,_,T,T,T,T,_,_,_,L,L,L,_,
_,L,L,L,L,L,_,T,_,_,_,_,_,_,_,
_,_,_,L,L,_,_,T,L,L,L,L,_,_,_,
_,_,_,_,_,_,_,T,_,_,_,_,_,_,_,
_,_,_,_,_,_,L,T,L,_,_,_,_,_,_,
_,_,_,_,L,L,L,L,L,L,L,_,_,_,_,
_,_,_,_,L,L,L,L,L,L,_,_,_,_,_,
_,_,_,_,_,_,L,L,L,_,_,_,_,_,_,
_,_,_,_,_,_,_,L,L,_,_,_,_,_,_,

_,_,_,_,_,T,T,T,T,T,_,_,_,_,_,
_,_,_,_,_,T,T,T,T,T,_,_,_,_,_,
_,_,_,_,_,T,T,T,T,T,_,_,_,_,_,
_,_,_,_,_,_,T,T,T,_,_,_,_,_,_,
_,_,_,_,_,_,T,T,T,_,_,_,_,_,_,
_,_,_,_,_,_,T,T,T,_,_,_,_,_,_,
_,_,_,_,_,_,T,T,T,_,_,_,_,_,_,
_,_,_,_,_,_,T,T,T,_,_,_,_,_,_,
_,_,_,_,_,_,_,T,_,_,_,_,_,_,_,
_,_,_,_,_,_,_,T,_,_,_,_,_,_,_,
_,_,_,_,_,_,_,T,_,_,_,_,_,_,_,
_,_,_,_,_,_,_,_,_,_,_,_,_,_,_,
_,_,_,_,_,_,_,_,_,_,_,_,_,_,_,
_,_,_,_,_,_,_,_,_,_,_,_,_,_,_,
_,_,_,_,_,_,_,_,_,_,_,L,L,L,L,
_,_,_,_,_,_,_,_,_,_,_,_,L,L,L,
_,_,_,_,_,_,_,_,_,_,_,_,_,_,_,
_,_,_,_,_,_,_,_,_,_,_,_,_,_,_,
_,_,_,_,_,_,_,T,T,_,_,_,_,_,_,
_,_,_,_,_,_,_,L,L,L,_,_,_,_,_,
L,L,L,L,L,_,_,_,L,_,_,_,_,_,_,
L,L,L,L,_,_,T,_,_,_,_,_,_,_,_,
_,_,_,_,_,_,_,_,_,_,_,_,_,_,_,
_,_,_,_,_,_,_,_,_,_,_,L,L,L,L,
_,_,_,_,T,_,_,_,_,_,_,_,_,_,_,
_,L,L,T,T,L,L,T,T,T,_,_,_,_,_,
_,_,L,L,L,_,_,L,L,T,L,L,_,_,_,
_,_,_,_,_,_,_,_,L,L,L,_,_,_,_,
_,_,_,_,_,_,_,L,_,_,_,_,_,_,_,
_,_,_,_,_,L,L,L,L,L,_,_,_,_,_,
_,_,_,_,_,L,L,L,L,L,_,_,_,_,_,
_,_,_,_,_,_,L,_,_,_,_,_,_,_,_,
_,_,_,_,_,_,_,_,_,_,_,_,_,_,_,

_,_,_,_,_,T,T,T,T,T,_,_,_,_,_,
_,_,_,_,_,_,T,T,T,_,_,_,_,_,_,
_,_,_,_,_,_,_,T,_,_,_,_,_,_,_,
_,_,_,_,_,_,_,_,_,_,_,_,_,_,_,
_,_,_,_,_,_,_,_,_,_,_,_,_,_,_,
_,_,_,_,_,_,_,_,_,_,_,_,_,_,_,
_,_,_,_,_,_,_,_,_,_,_,_,_,_,_,
_,_,_,_,_,_,_,_,_,_,_,_,_,_,_,
_,_,_,_,_,_,_,_,_,_,_,_,_,_,_,
_,_,_,_,_,_,_,_,_,_,_,_,_,_,_,
_,_,_,_,_,_,_,_,_,_,_,_,_,_,_,
_,_,_,_,_,_,_,_,_,_,_,_,_,_,_,
_,_,_,_,_,_,_,_,_,_,_,_,_,_,_,
_,_,_,_,_,_,_,_,_,_,_,_,_,_,_,
_,_,_,_,_,_,_,_,_,_,_,L,L,L,L,
_,_,_,_,_,_,_,_,_,_,_,_,_,_,_,
_,_,_,_,_,_,_,_,_,_,_,_,_,_,_,
_,_,_,_,_,_,_,_,_,_,_,_,_,_,_,
_,_,_,_,_,_,_,_,T,_,_,_,_,_,_,
_,_,_,_,_,_,_,L,L,L,_,_,_,_,_,
L,L,L,L,_,_,_,_,L,L,_,_,_,_,_,
_,_,_,_,_,_,T,_,_,_,_,_,_,_,_,
_,_,_,_,_,L,L,L,L,_,_,_,_,_,_,
_,_,_,_,_,_,_,_,_,_,_,_,_,_,_,
_,_,_,_,_,_,_,_,_,_,_,_,_,_,_,
_,L,L,L,L,L,L,_,_,_,_,_,_,_,_,
_,_,_,L,L,_,_,L,L,T,L,L,_,_,_,
_,_,_,_,_,_,_,_,L,L,L,_,_,_,_,
_,_,_,_,_,_,_,_,_,_,_,_,_,_,_,
_,_,_,_,_,_,L,L,L,_,_,_,_,_,_,
_,_,_,_,_,_,L,L,_,_,_,_,_,_,_,
_,_,_,_,_,_,_,_,_,_,_,_,_,_,_,
_,_,_,_,_,_,_,_,_,_,_,_,_,_,_,

_,_,_,_,_,_,_,_,_,_,_,_,_,_,_,
_,_,_,_,_,_,_,_,_,_,_,_,_,_,_,
_,_,_,_,_,_,_,_,_,_,_,_,_,_,_,
_,_,_,_,_,_,_,_,_,_,_,_,_,_,_,
_,_,_,_,_,_,_,_,_,_,_,_,_,_,_,
_,_,_,_,_,_,_,_,_,_,_,_,_,_,_,
_,_,_,_,_,_,_,_,_,_,_,_,_,_,_,
_,_,_,_,_,_,_,_,_,_,_,_,_,_,_,
_,_,_,_,_,_,_,_,_,_,_,_,_,_,_,
_,_,_,_,_,_,_,_,_,_,_,_,_,_,_,
_,_,_,_,_,_,_,_,_,_,_,_,_,_,_,
_,_,_,_,_,_,_,_,_,_,_,_,_,_,_,
_,_,_,_,_,_,_,_,_,_,_,_,_,_,_,
_,_,_,_,_,_,_,_,_,_,_,_,_,_,_,
_,_,_,_,_,_,_,_,_,_,_,_,_,_,_,
_,_,_,_,_,_,_,_,_,_,_,_,_,_,_,
_,_,_,_,_,_,_,_,_,_,_,_,_,_,_,
_,_,_,_,_,_,_,_,_,_,_,_,_,_,_,
_,_,_,_,_,_,_,_,_,_,_,_,_,_,_,
_,_,_,_,_,_,_,L,L,L,_,_,_,_,_,
_,_,_,_,_,_,_,_,_,_,_,_,_,_,_,
_,_,_,_,_,_,T,_,_,_,_,_,_,_,_,
_,_,_,_,L,L,L,L,L,_,_,_,_,_,_,
_,_,_,_,_,_,_,_,_,_,_,_,_,_,_,
_,_,_,_,_,_,_,_,_,_,_,_,_,_,_,
_,_,L,L,L,L,_,_,_,_,_,_,_,_,_,
_,_,_,_,_,_,_,L,L,L,L,L,_,_,_,
_,_,_,_,_,_,_,_,_,L,_,_,_,_,_,
_,_,_,_,_,_,_,_,_,_,_,_,_,_,_,
_,_,_,_,_,_,_,L,L,_,_,_,_,_,_,
_,_,_,_,_,_,_,_,_,_,_,_,_,_,_,
_,_,_,_,_,_,_,_,_,_,_,_,_,_,_,
_,_,_,_,_,_,_,_,_,_,_,_,_,_,_,

_,_,_,_,_,_,_,_,_,_,_,_,_,_,_,
_,_,_,_,_,_,_,_,_,_,_,_,_,_,_,
_,_,_,_,_,_,_,_,_,_,_,_,_,_,_,
_,_,_,_,_,_,_,_,_,_,_,_,_,_,_,
_,_,_,_,_,_,_,_,_,_,_,_,_,_,_,
_,_,_,_,_,_,_,_,_,_,_,_,_,_,_,
_,_,_,_,_,_,_,_,_,_,_,_,_,_,_,
_,_,_,_,_,_,_,_,_,_,_,_,_,_,_,
_,_,_,_,_,_,_,_,_,_,_,_,_,_,_,
_,_,_,_,_,_,_,_,_,_,_,_,_,_,_,
_,_,_,_,_,_,_,_,_,_,_,_,_,_,_,
_,_,_,_,_,_,_,_,_,_,_,_,_,_,_,
_,_,_,_,_,_,_,_,_,_,_,_,_,_,_,
_,_,_,_,_,_,_,_,_,_,_,_,_,_,_,
_,_,_,_,_,_,_,_,_,_,_,_,_,_,_,
_,_,_,_,_,_,_,_,_,_,_,_,_,_,_,
_,_,_,_,_,_,_,_,_,_,_,_,_,_,_,
_,_,_,_,_,_,_,_,_,_,_,_,_,_,_,
_,_,_,_,_,_,_,_,_,_,_,_,_,_,_,
_,_,_,_,_,_,_,_,_,_,_,_,_,_,_,
_,_,_,_,_,_,_,_,_,_,_,_,_,_,_,
_,_,_,_,_,_,T,_,_,_,_,_,_,_,_,
_,_,_,_,L,L,T,L,L,_,_,_,_,_,_,
_,_,_,_,_,L,L,L,_,_,_,_,_,_,_,
_,_,_,_,_,_,_,_,_,_,_,_,_,_,_,
_,_,_,_,_,_,_,_,_,_,_,_,_,_,_,
_,_,_,_,_,_,_,_,L,L,L,_,_,_,_,
_,_,_,_,_,_,_,_,_,_,_,_,_,_,_,
_,_,_,_,_,_,_,_,_,_,_,_,_,_,_,
_,_,_,_,_,_,_,_,_,_,_,_,_,_,_,
_,_,_,_,_,_,_,_,_,_,_,_,_,_,_,
_,_,_,_,_,_,_,_,_,_,_,_,_,_,_,
_,_,_,_,_,_,_,_,_,_,_,_,_,_,_,

_,_,_,_,_,_,_,_,_,_,_,_,_,_,_,
_,_,_,_,_,_,_,_,_,_,_,_,_,_,_,
_,_,_,_,_,_,_,_,_,_,_,_,_,_,_,
_,_,_,_,_,_,_,_,_,_,_,_,_,_,_,
_,_,_,_,_,_,_,_,_,_,_,_,_,_,_,
_,_,_,_,_,_,_,_,_,_,_,_,_,_,_,
_,_,_,_,_,_,_,_,_,_,_,_,_,_,_,
_,_,_,_,_,_,_,_,_,_,_,_,_,_,_,
_,_,_,_,_,_,_,_,_,_,_,_,_,_,_,
_,_,_,_,_,_,_,_,_,_,_,_,_,_,_,
_,_,_,_,_,_,_,_,_,_,_,_,_,_,_,
_,_,_,_,_,_,_,_,_,_,_,_,_,_,_,
_,_,_,_,_,_,_,_,_,_,_,_,_,_,_,
_,_,_,_,_,_,_,_,_,_,_,_,_,_,_,
_,_,_,_,_,_,_,_,_,_,_,_,_,_,_,
_,_,_,_,_,_,_,_,_,_,_,_,_,_,_,
_,_,_,_,_,_,_,_,_,_,_,_,_,_,_,
_,_,_,_,_,_,_,_,_,_,_,_,_,_,_,
_,_,_,_,_,_,_,_,_,_,_,_,_,_,_,
_,_,_,_,_,_,_,_,_,_,_,_,_,_,_,
_,_,_,_,_,_,_,_,_,_,_,_,_,_,_,
_,_,_,_,_,_,_,_,_,_,_,_,_,_,_,
_,_,_,_,L,L,T,L,L,_,_,_,_,_,_,
_,_,_,_,_,L,L,L,_,_,_,_,_,_,_,
_,_,_,_,_,_,_,_,_,_,_,_,_,_,_,
_,_,_,_,_,_,_,_,_,_,_,_,_,_,_,
_,_,_,_,_,_,_,_,_,_,_,_,_,_,_,
_,_,_,_,_,_,_,_,_,_,_,_,_,_,_,
_,_,_,_,_,_,_,_,_,_,_,_,_,_,_,
_,_,_,_,_,_,_,_,_,_,_,_,_,_,_,
_,_,_,_,_,_,_,_,_,_,_,_,_,_,_,
_,_,_,_,_,_,_,_,_,_,_,_,_,_,_,
_,_,_,_,_,_,_,_,_,_,_,_,_,_,_,

_,_,_,_,_,_,_,_,_,_,_,_,_,_,_,
_,_,_,_,_,_,_,_,_,_,_,_,_,_,_,
_,_,_,_,_,_,_,_,_,_,_,_,_,_,_,
_,_,_,_,_,_,_,_,_,_,_,_,_,_,_,
_,_,_,_,_,_,_,_,_,_,_,_,_,_,_,
_,_,_,_,_,_,_,_,_,_,_,_,_,_,_,
_,_,_,_,_,_,_,_,_,_,_,_,_,_,_,
_,_,_,_,_,_,_,_,_,_,_,_,_,_,_,
_,_,_,_,_,_,_,_,_,_,_,_,_,_,_,
_,_,_,_,_,_,_,_,_,_,_,_,_,_,_,
_,_,_,_,_,_,_,_,_,_,_,_,_,_,_,
_,_,_,_,_,_,_,_,_,_,_,_,_,_,_,
_,_,_,_,_,_,_,_,_,_,_,_,_,_,_,
_,_,_,_,_,_,_,_,_,_,_,_,_,_,_,
_,_,_,_,_,_,_,_,_,_,_,_,_,_,_,
_,_,_,_,_,_,_,_,_,_,_,_,_,_,_,
_,_,_,_,_,_,_,_,_,_,_,_,_,_,_,
_,_,_,_,_,_,_,_,_,_,_,_,_,_,_,
_,_,_,_,_,_,_,_,_,_,_,_,_,_,_,
_,_,_,_,_,_,_,_,_,_,_,_,_,_,_,
_,_,_,_,_,_,_,_,_,_,_,_,_,_,_,
_,_,_,_,_,_,_,_,_,_,_,_,_,_,_,
_,_,_,_,L,L,L,L,L,_,_,_,_,_,_,
_,_,_,_,_,_,L,_,_,_,_,_,_,_,_,
_,_,_,_,_,_,_,_,_,_,_,_,_,_,_,
_,_,_,_,_,_,_,_,_,_,_,_,_,_,_,
_,_,_,_,_,_,_,_,_,_,_,_,_,_,_,
_,_,_,_,_,_,_,_,_,_,_,_,_,_,_,
_,_,_,_,_,_,_,_,_,_,_,_,_,_,_,
_,_,_,_,_,_,_,_,_,_,_,_,_,_,_,
_,_,_,_,_,_,_,_,_,_,_,_,_,_,_,
_,_,_,_,_,_,_,_,_,_,_,_,_,_,_,
_,_,_,_,_,_,_,_,_,_,_,_,_,_,_,

	}
}
