
local _ = {name = "air", prob = 0}
local M = {name = "ethereal:mushroom", prob = 255}
local T = {name = "ethereal:mushroom_trunk", prob = 255}
local P = {name = "ethereal:mushroom_pore", prob = 255}

ethereal.mushroomone = {

	size = {x = 8, y = 11, z = 8},

	yslice_prob = {
		{ypos = 0, prob = 127},
		{ypos = 1, prob = 127},
		{ypos = 7, prob = 127},
	},

	data = {

	_,_,_,_,_,_,_,_,
	_,_,_,_,_,_,_,_,
	_,_,_,_,_,_,_,_,
	_,_,_,_,_,_,_,_,
	_,_,_,_,_,_,_,_,
	_,_,_,_,_,_,_,_,
	_,_,_,_,_,_,_,_,
	_,_,_,M,M,_,_,_,
	_,_,_,M,M,_,_,_,
	_,_,_,_,_,_,_,_,
	_,_,_,_,_,_,_,_,

	_,_,_,_,_,_,_,_,
	_,_,_,_,_,_,_,_,
	_,_,_,_,_,_,_,_,
	_,_,_,_,_,_,_,_,
	_,_,_,_,_,_,_,_,
	_,_,_,_,_,_,_,_,
	_,_,_,_,_,_,_,_,
	_,_,M,_,_,M,_,_,
	_,_,M,_,_,M,_,_,
	_,_,_,M,M,_,_,_,
	_,_,_,_,_,_,_,_,

	_,_,_,_,_,_,_,_,
	_,_,_,_,_,_,_,_,
	_,_,_,_,_,_,_,_,
	_,_,_,_,_,_,_,_,
	_,_,_,_,_,_,_,_,
	_,_,_,_,_,_,_,_,
	_,_,_,_,_,_,_,_,
	_,M,_,_,_,_,M,_,
	_,M,_,_,_,_,M,_,
	_,_,M,P,P,M,_,_,
	_,_,_,M,M,_,_,_,

	_,_,_,T,T,_,_,_,
	_,_,_,T,T,_,_,_,
	_,_,_,T,T,_,_,_,
	_,_,_,T,T,_,_,_,
	_,_,_,T,T,_,_,_,
	_,_,_,T,T,_,_,_,
	_,_,_,T,T,_,_,_,
	M,_,_,T,T,_,_,M,
	M,_,_,T,T,_,_,M,
	_,M,P,P,P,P,M,_,
	_,_,M,M,M,M,_,_,

	_,_,_,T,T,_,_,_,
	_,_,_,T,T,_,_,_,
	_,_,_,T,T,_,_,_,
	_,_,_,T,T,_,_,_,
	_,_,_,T,T,_,_,_,
	_,_,_,T,T,_,_,_,
	_,_,_,T,T,_,_,_,
	M,_,_,T,T,_,_,M,
	M,_,_,T,T,_,_,M,
	_,M,P,P,P,P,M,_,
	_,_,M,M,M,M,_,_,

	_,_,_,_,_,_,_,_,
	_,_,_,_,_,_,_,_,
	_,_,_,_,_,_,_,_,
	_,_,_,_,_,_,_,_,
	_,_,_,_,_,_,_,_,
	_,_,_,_,_,_,_,_,
	_,_,_,_,_,_,_,_,
	_,M,_,_,_,_,M,_,
	_,M,_,_,_,_,M,_,
	_,_,M,P,P,M,_,_,
	_,_,_,M,M,_,_,_,

	_,_,_,_,_,_,_,_,
	_,_,_,_,_,_,_,_,
	_,_,_,_,_,_,_,_,
	_,_,_,_,_,_,_,_,
	_,_,_,_,_,_,_,_,
	_,_,_,_,_,_,_,_,
	_,_,_,_,_,_,_,_,
	_,_,M,_,_,M,_,_,
	_,_,M,_,_,M,_,_,
	_,_,_,M,M,_,_,_,
	_,_,_,_,_,_,_,_,

	_,_,_,_,_,_,_,_,
	_,_,_,_,_,_,_,_,
	_,_,_,_,_,_,_,_,
	_,_,_,_,_,_,_,_,
	_,_,_,_,_,_,_,_,
	_,_,_,_,_,_,_,_,
	_,_,_,_,_,_,_,_,
	_,_,_,M,M,_,_,_,
	_,_,_,M,M,_,_,_,
	_,_,_,_,_,_,_,_,
	_,_,_,_,_,_,_,_,

	}
}
