local n1 = { name = "default:dirt_with_grass" }
local n2 = { name = "air" }
local n3 = { name = "stairs:stair_wood", param2 = 1 }
local n4 = { name = "stairs:stair_wood", param2 = 3 }
local n5 = { name = "stairs:stair_junglewood", param2 = 20 }
local n6 = { name = "default:tree", param2 = 1 }
local n7 = { name = "default:cobble" }
local n8 = { name = "default:tree" }
local n9 = { name = "default:tree", param2 = 12 }
local n10 = { name = "xpanes:pane_flat" }
local n11 = { name = "default:dirt" }
local n12 = { name = "default:tree", param2 = 3 }
local n13 = { name = "default:tree", param2 = 20 }
local n14 = { name = "default:tree", param2 = 21 }
local n15 = { name = "stairs:stair_junglewood", param2 = 23 }
local n16 = { name = "stairs:stair_stone_block", param2 = 2 }
local n17 = { name = "stairs:stair_junglewood", param2 = 21 }
local n18 = { name = "default:bookshelf", param2 = 3 }
local n19 = { name = "default:torch_wall", param2 = 5 }
local n20 = { name = "default:bookshelf", param2 = 1 }
local n21 = { name = "default:junglewood" }
local n22 = { name = "default:chest", param2 = 3 }
local n23 = { name = "default:torch_wall", param2 = 4 }
local n24 = { name = "doors:door_wood_a", param2 = 1 }
local n25 = { name = "xpanes:pane_flat", param2 = 3 }
local n26 = { name = "doors:hidden", param2 = 1 }
local n27 = { name = "default:sign_wall_steel", param2 = 3 }
local n28 = { name = "default:tree", param2 = 18 }
local n29 = { name = "stairs:stair_junglewood", param2 = 3 }
local n30 = { name = "default:fence_wood" }
local n31 = { name = "stairs:stair_junglewood", param2 = 1 }
local n32 = { name = "doors:trapdoor" }
local n33 = { name = "default:tree", param2 = 2 }
local n34 = { name = "default:tree", param2 = 22 }
local n35 = { name = "stairs:stair_junglewood", param2 = 22 }

return {
	yslice_prob = {
		
	},
	size = {
		y = 12,
		x = 10,
		z = 11
	}
,
	data = {


		-- z=-10, y=-11
		n1, n1, n1, n1, n1, n1, n1, n1, n1, n1, 
		-- z=-10, y=-10
		n2, n2, n2, n2, n2, n2, n2, n2, n2, n2, 
		-- z=-10, y=-9
		n2, n2, n2, n2, n2, n2, n2, n2, n2, n2, 
		-- z=-10, y=-8
		n2, n2, n2, n2, n2, n2, n2, n2, n2, n2, 
		-- z=-10, y=-7
		n2, n2, n2, n2, n2, n2, n2, n2, n2, n2, 
		-- z=-10, y=-6
		n2, n2, n2, n2, n2, n2, n2, n2, n2, n2, 
		-- z=-10, y=-5
		n2, n2, n2, n2, n2, n2, n2, n2, n2, n2, 
		-- z=-10, y=-4
		n3, n2, n2, n2, n2, n2, n2, n2, n2, n4, 
		-- z=-10, y=-3
		n2, n3, n2, n2, n2, n2, n2, n2, n4, n2, 
		-- z=-10, y=-2
		n2, n2, n3, n2, n2, n2, n2, n4, n2, n2, 
		-- z=-10, y=-1
		n2, n2, n2, n3, n2, n2, n4, n2, n2, n2, 
		-- z=-10, y=0
		n2, n2, n2, n2, n3, n4, n2, n2, n2, n2, 

		-- z=-9, y=-11
		n1, n1, n1, n1, n1, n1, n1, n1, n1, n1, 
		-- z=-9, y=-10
		n2, n2, n2, n2, n2, n2, n2, n2, n2, n2, 
		-- z=-9, y=-9
		n2, n2, n2, n2, n2, n2, n2, n2, n2, n2, 
		-- z=-9, y=-8
		n2, n2, n2, n2, n2, n2, n2, n2, n2, n2, 
		-- z=-9, y=-7
		n2, n2, n5, n5, n5, n5, n5, n5, n2, n2, 
		-- z=-9, y=-6
		n2, n6, n7, n7, n7, n7, n7, n7, n8, n2, 
		-- z=-9, y=-5
		n2, n6, n7, n7, n7, n7, n7, n7, n8, n2, 
		-- z=-9, y=-4
		n3, n9, n9, n9, n9, n9, n9, n9, n9, n4, 
		-- z=-9, y=-3
		n2, n3, n7, n7, n10, n10, n7, n7, n4, n2, 
		-- z=-9, y=-2
		n2, n2, n3, n7, n7, n7, n7, n4, n2, n2, 
		-- z=-9, y=-1
		n2, n2, n2, n3, n7, n7, n4, n2, n2, n2, 
		-- z=-9, y=0
		n2, n2, n2, n2, n3, n4, n2, n2, n2, n2, 

		-- z=-8, y=-11
		n1, n1, n11, n11, n11, n11, n11, n11, n1, n1, 
		-- z=-8, y=-10
		n2, n2, n8, n7, n7, n7, n7, n12, n2, n2, 
		-- z=-8, y=-9
		n2, n2, n13, n7, n10, n10, n7, n12, n2, n2, 
		-- z=-8, y=-8
		n2, n2, n13, n7, n7, n7, n7, n14, n2, n2, 
		-- z=-8, y=-7
		n2, n15, n7, n16, n7, n7, n7, n7, n17, n2, 
		-- z=-8, y=-6
		n2, n7, n2, n2, n2, n2, n2, n2, n7, n2, 
		-- z=-8, y=-5
		n2, n7, n2, n2, n2, n2, n2, n2, n7, n2, 
		-- z=-8, y=-4
		n3, n18, n2, n2, n19, n2, n2, n2, n20, n4, 
		-- z=-8, y=-3
		n2, n3, n2, n2, n2, n2, n2, n2, n4, n2, 
		-- z=-8, y=-2
		n2, n2, n3, n2, n2, n2, n2, n4, n2, n2, 
		-- z=-8, y=-1
		n2, n2, n2, n3, n2, n2, n4, n2, n2, n2, 
		-- z=-8, y=0
		n2, n2, n2, n2, n3, n4, n2, n2, n2, n2, 

		-- z=-7, y=-11
		n1, n1, n11, n21, n21, n21, n21, n11, n1, n1, 
		-- z=-7, y=-10
		n2, n2, n7, n2, n2, n2, n2, n7, n2, n2, 
		-- z=-7, y=-9
		n2, n2, n7, n2, n2, n2, n2, n7, n2, n2, 
		-- z=-7, y=-8
		n2, n2, n7, n16, n2, n2, n2, n7, n2, n2, 
		-- z=-7, y=-7
		n2, n15, n7, n2, n2, n2, n2, n7, n17, n2, 
		-- z=-7, y=-6
		n2, n7, n2, n2, n2, n2, n2, n2, n7, n2, 
		-- z=-7, y=-5
		n2, n7, n2, n2, n2, n2, n2, n2, n7, n2, 
		-- z=-7, y=-4
		n3, n18, n2, n2, n2, n2, n2, n2, n20, n4, 
		-- z=-7, y=-3
		n2, n3, n2, n2, n2, n2, n2, n2, n4, n2, 
		-- z=-7, y=-2
		n2, n2, n3, n2, n2, n2, n2, n4, n2, n2, 
		-- z=-7, y=-1
		n2, n2, n2, n3, n2, n2, n4, n2, n2, n2, 
		-- z=-7, y=0
		n2, n2, n2, n2, n3, n4, n2, n2, n2, n2, 

		-- z=-6, y=-11
		n1, n1, n11, n21, n21, n21, n21, n11, n1, n1, 
		-- z=-6, y=-10
		n2, n2, n7, n22, n2, n2, n2, n7, n2, n2, 
		-- z=-6, y=-9
		n2, n2, n7, n16, n2, n2, n2, n7, n2, n2, 
		-- z=-6, y=-8
		n2, n2, n7, n2, n2, n2, n2, n7, n2, n2, 
		-- z=-6, y=-7
		n2, n15, n7, n2, n2, n2, n2, n7, n17, n2, 
		-- z=-6, y=-6
		n2, n7, n2, n2, n2, n2, n2, n2, n7, n2, 
		-- z=-6, y=-5
		n2, n7, n2, n2, n2, n2, n2, n2, n7, n2, 
		-- z=-6, y=-4
		n3, n18, n2, n2, n2, n23, n2, n2, n20, n4, 
		-- z=-6, y=-3
		n2, n3, n2, n2, n2, n2, n2, n2, n4, n2, 
		-- z=-6, y=-2
		n2, n2, n3, n2, n2, n2, n2, n4, n2, n2, 
		-- z=-6, y=-1
		n2, n2, n2, n3, n2, n2, n4, n2, n2, n2, 
		-- z=-6, y=0
		n2, n2, n2, n2, n3, n4, n2, n2, n2, n2, 

		-- z=-5, y=-11
		n1, n1, n11, n21, n21, n21, n21, n21, n1, n1, 
		-- z=-5, y=-10
		n2, n2, n7, n16, n2, n2, n2, n24, n2, n2, 
		-- z=-5, y=-9
		n2, n2, n25, n2, n2, n2, n2, n26, n2, n2, 
		-- z=-5, y=-8
		n2, n2, n7, n2, n2, n2, n2, n7, n27, n2, 
		-- z=-5, y=-7
		n2, n15, n7, n2, n2, n2, n2, n7, n17, n2, 
		-- z=-5, y=-6
		n2, n7, n2, n2, n2, n2, n2, n2, n7, n2, 
		-- z=-5, y=-5
		n2, n7, n2, n2, n2, n2, n2, n2, n7, n2, 
		-- z=-5, y=-4
		n3, n9, n9, n9, n9, n9, n9, n28, n28, n4, 
		-- z=-5, y=-3
		n2, n3, n2, n2, n2, n2, n2, n2, n4, n2, 
		-- z=-5, y=-2
		n2, n2, n3, n2, n2, n2, n2, n4, n2, n2, 
		-- z=-5, y=-1
		n2, n2, n2, n3, n2, n2, n4, n2, n2, n2, 
		-- z=-5, y=0
		n2, n2, n2, n2, n3, n4, n2, n2, n2, n2, 

		-- z=-4, y=-11
		n1, n1, n11, n21, n21, n21, n21, n11, n1, n1, 
		-- z=-4, y=-10
		n2, n2, n7, n2, n2, n2, n2, n7, n2, n2, 
		-- z=-4, y=-9
		n2, n2, n7, n2, n2, n2, n2, n7, n2, n2, 
		-- z=-4, y=-8
		n2, n2, n7, n2, n2, n2, n2, n7, n2, n2, 
		-- z=-4, y=-7
		n2, n15, n7, n2, n2, n2, n2, n7, n17, n2, 
		-- z=-4, y=-6
		n2, n7, n2, n2, n2, n2, n2, n2, n7, n2, 
		-- z=-4, y=-5
		n2, n7, n2, n2, n2, n2, n2, n2, n7, n2, 
		-- z=-4, y=-4
		n3, n18, n2, n2, n19, n2, n2, n2, n20, n4, 
		-- z=-4, y=-3
		n2, n3, n2, n2, n2, n2, n2, n2, n4, n2, 
		-- z=-4, y=-2
		n2, n2, n3, n2, n2, n2, n2, n4, n2, n2, 
		-- z=-4, y=-1
		n2, n2, n2, n3, n2, n2, n4, n2, n2, n2, 
		-- z=-4, y=0
		n2, n2, n2, n2, n3, n4, n2, n2, n2, n2, 

		-- z=-3, y=-11
		n1, n1, n11, n21, n21, n21, n21, n11, n1, n1, 
		-- z=-3, y=-10
		n2, n2, n7, n29, n30, n30, n31, n7, n2, n2, 
		-- z=-3, y=-9
		n2, n2, n7, n2, n32, n32, n2, n7, n2, n2, 
		-- z=-3, y=-8
		n2, n2, n7, n2, n2, n2, n2, n7, n2, n2, 
		-- z=-3, y=-7
		n2, n15, n7, n2, n2, n2, n2, n7, n17, n2, 
		-- z=-3, y=-6
		n2, n7, n2, n2, n2, n2, n2, n2, n7, n2, 
		-- z=-3, y=-5
		n2, n7, n2, n2, n2, n2, n2, n2, n7, n2, 
		-- z=-3, y=-4
		n3, n18, n2, n2, n2, n2, n2, n2, n20, n4, 
		-- z=-3, y=-3
		n2, n3, n2, n2, n2, n2, n2, n2, n4, n2, 
		-- z=-3, y=-2
		n2, n2, n3, n2, n2, n2, n2, n4, n2, n2, 
		-- z=-3, y=-1
		n2, n2, n2, n3, n2, n2, n4, n2, n2, n2, 
		-- z=-3, y=0
		n2, n2, n2, n2, n3, n4, n2, n2, n2, n2, 

		-- z=-2, y=-11
		n1, n1, n11, n11, n11, n11, n11, n11, n1, n1, 
		-- z=-2, y=-10
		n2, n2, n33, n7, n7, n7, n7, n33, n2, n2, 
		-- z=-2, y=-9
		n2, n2, n33, n7, n10, n10, n7, n34, n2, n2, 
		-- z=-2, y=-8
		n2, n2, n34, n7, n7, n7, n7, n34, n2, n2, 
		-- z=-2, y=-7
		n2, n15, n7, n7, n7, n7, n7, n7, n17, n2, 
		-- z=-2, y=-6
		n2, n7, n2, n2, n2, n2, n2, n2, n7, n2, 
		-- z=-2, y=-5
		n2, n7, n2, n2, n2, n2, n2, n2, n7, n2, 
		-- z=-2, y=-4
		n3, n18, n2, n2, n2, n23, n2, n2, n20, n4, 
		-- z=-2, y=-3
		n2, n3, n2, n2, n2, n2, n2, n2, n4, n2, 
		-- z=-2, y=-2
		n2, n2, n3, n2, n2, n2, n2, n4, n2, n2, 
		-- z=-2, y=-1
		n2, n2, n2, n3, n2, n2, n4, n2, n2, n2, 
		-- z=-2, y=0
		n2, n2, n2, n2, n3, n4, n2, n2, n2, n2, 

		-- z=-1, y=-11
		n1, n1, n1, n1, n1, n1, n1, n1, n1, n1, 
		-- z=-1, y=-10
		n2, n2, n2, n2, n2, n2, n2, n2, n2, n2, 
		-- z=-1, y=-9
		n2, n2, n2, n2, n2, n2, n2, n2, n2, n2, 
		-- z=-1, y=-8
		n2, n2, n2, n2, n2, n2, n2, n2, n2, n2, 
		-- z=-1, y=-7
		n2, n2, n35, n35, n35, n35, n35, n35, n2, n2, 
		-- z=-1, y=-6
		n2, n33, n7, n7, n7, n7, n7, n7, n12, n2, 
		-- z=-1, y=-5
		n2, n33, n7, n7, n7, n7, n7, n7, n12, n2, 
		-- z=-1, y=-4
		n3, n28, n9, n9, n9, n9, n9, n9, n9, n4, 
		-- z=-1, y=-3
		n2, n3, n7, n7, n10, n10, n7, n7, n4, n2, 
		-- z=-1, y=-2
		n2, n2, n3, n7, n7, n7, n7, n4, n2, n2, 
		-- z=-1, y=-1
		n2, n2, n2, n3, n7, n7, n4, n2, n2, n2, 
		-- z=-1, y=0
		n2, n2, n2, n2, n3, n4, n2, n2, n2, n2, 

		-- z=0, y=-11
		n1, n1, n1, n1, n1, n1, n1, n1, n1, n1, 
		-- z=0, y=-10
		n2, n2, n2, n2, n2, n2, n2, n2, n2, n2, 
		-- z=0, y=-9
		n2, n2, n2, n2, n2, n2, n2, n2, n2, n2, 
		-- z=0, y=-8
		n2, n2, n2, n2, n2, n2, n2, n2, n2, n2, 
		-- z=0, y=-7
		n2, n2, n2, n2, n2, n2, n2, n2, n2, n2, 
		-- z=0, y=-6
		n2, n2, n2, n2, n2, n2, n2, n2, n2, n2, 
		-- z=0, y=-5
		n2, n2, n2, n2, n2, n2, n2, n2, n2, n2, 
		-- z=0, y=-4
		n3, n2, n2, n2, n2, n2, n2, n2, n2, n4, 
		-- z=0, y=-3
		n2, n3, n2, n2, n2, n2, n2, n2, n4, n2, 
		-- z=0, y=-2
		n2, n2, n3, n2, n2, n2, n2, n4, n2, n2, 
		-- z=0, y=-1
		n2, n2, n2, n3, n2, n2, n4, n2, n2, n2, 
		-- z=0, y=0
		n2, n2, n2, n2, n3, n4, n2, n2, n2, n2, 
}
}
