
local _ = {name = "air", prob = 0}
local L = {name = "ethereal:willow_twig", prob = 255}
local T = {name = "ethereal:willow_trunk", prob = 255}
local t = {name = "ethereal:willow_trunk", prob = 127}

ethereal.willow = {

	size = {x = 12, y = 14, z = 12},

	yslice_prob = {
		{ypos = 0, prob = 127},
		{ypos = 1, prob = 127},
	},

	data = {

	_,_,_,_,_,_,_,_,_,_,_,_,
	_,_,_,_,_,_,_,_,_,_,_,_,
	_,_,_,_,_,_,_,_,_,_,_,_,
	_,_,_,_,_,_,_,_,_,_,_,_,
	_,_,_,_,_,_,L,_,_,_,_,_,
	_,_,_,_,L,_,L,_,_,_,_,_,
	_,_,_,_,L,L,L,L,_,_,_,_,
	_,_,_,_,_,_,L,_,_,_,_,_,
	_,_,_,_,_,_,_,_,_,_,_,_,
	_,_,_,_,_,_,_,_,_,_,_,_,
	_,_,_,_,_,_,_,_,_,_,_,_,
	_,_,_,_,_,_,_,_,_,_,_,_,
	_,_,_,_,_,_,_,_,_,_,_,_,
	_,_,_,_,_,_,_,_,_,_,_,_,

	_,_,_,_,_,_,_,_,_,_,_,_,
	_,_,_,_,_,_,_,_,_,_,_,_,
	_,_,_,_,_,_,_,_,_,_,_,_,
	_,_,_,_,_,_,_,_,_,_,_,_,
	_,_,_,_,_,_,_,_,_,_,_,_,
	_,_,_,_,_,L,L,L,L,_,_,_,
	_,_,L,L,L,L,T,L,L,_,_,_,
	_,_,_,_,_,L,L,L,_,_,_,_,
	_,_,_,_,_,L,L,_,_,_,_,_,
	_,_,_,_,_,_,_,_,_,_,_,_,
	_,_,_,_,_,_,_,_,_,_,_,_,
	_,_,_,_,_,_,_,_,_,_,_,_,
	_,_,_,_,_,_,_,_,_,_,_,_,
	_,_,_,_,_,_,_,_,_,_,_,_,

	_,_,_,t,_,_,_,_,_,_,_,_,
	_,_,_,_,_,_,_,_,_,_,_,_,
	_,_,_,_,_,_,_,_,_,_,_,_,
	_,_,_,L,_,_,_,_,_,_,_,_,
	_,_,_,L,_,L,_,L,_,_,_,_,
	_,_,_,L,L,L,L,L,L,L,_,_,
	_,_,L,L,L,T,T,L,L,_,_,_,
	_,_,_,L,L,L,L,L,L,_,_,_,
	_,_,_,L,L,L,L,L,L,_,_,_,
	_,_,_,L,L,L,L,_,_,_,_,_,
	_,_,_,_,_,L,L,_,_,_,_,_,
	_,_,_,_,_,_,_,_,_,_,_,_,
	_,_,_,_,_,_,_,_,_,_,_,_,
	_,_,_,_,_,_,_,_,_,_,_,_,

	_,_,t,T,T,T,_,_,t,_,_,_,
	_,_,_,_,_,_,_,_,_,_,_,_,
	_,_,_,_,_,_,_,_,_,_,_,_,
	_,_,_,_,_,_,_,_,_,_,_,_,
	_,L,_,L,_,_,_,_,_,_,_,_,
	_,L,L,L,L,L,L,_,L,L,L,_,
	_,L,T,T,L,T,L,L,L,L,_,_,
	_,_,L,L,L,L,L,L,L,L,_,_,
	_,_,L,L,L,L,L,L,T,L,_,_,
	_,_,L,L,L,L,L,L,L,_,_,_,
	_,_,L,L,L,L,L,_,_,_,_,_,
	_,_,_,_,L,L,L,_,_,_,_,_,
	_,_,_,_,_,L,_,_,_,_,_,_,
	_,_,_,_,_,_,_,_,_,_,_,_,

	_,_,_,_,_,T,_,_,T,_,_,_,
	_,_,_,_,_,T,_,_,_,_,_,_,
	_,_,_,_,_,_,_,_,_,_,_,_,
	_,_,_,_,_,_,_,_,_,L,_,_,
	_,_,_,_,_,L,L,_,_,L,_,_,
	_,_,L,L,_,L,L,L,L,L,L,_,
	L,L,L,T,L,T,L,L,T,L,L,_,
	_,L,L,L,L,L,L,L,L,L,L,_,
	_,L,L,L,L,L,L,L,T,T,L,_,
	_,L,L,L,L,L,L,L,L,L,L,_,
	_,L,T,T,T,T,T,L,L,_,_,_,
	_,_,L,L,L,L,L,L,_,_,_,_,
	_,_,_,_,L,T,L,L,_,_,_,_,
	_,_,_,_,_,L,_,_,_,_,_,_,

	_,_,_,_,_,T,T,T,T,t,_,_,
	_,_,_,_,_,T,T,_,_,_,_,_,
	_,_,_,_,_,T,T,_,_,_,_,_,
	_,L,_,_,_,T,T,_,_,_,_,_,
	_,L,L,_,_,T,_,_,_,L,L,_,
	_,L,L,L,_,T,L,L,L,L,L,L,
	L,L,L,T,L,T,T,T,T,T,L,_,
	_,L,L,L,L,T,L,L,L,L,L,_,
	_,_,L,L,L,T,T,T,T,L,L,_,
	_,_,L,L,L,L,L,L,L,L,_,_,
	_,_,L,T,L,T,T,L,L,_,_,_,
	_,_,_,L,L,T,T,L,_,_,_,_,
	_,_,_,L,L,L,L,L,_,_,_,_,
	_,_,_,_,L,L,L,_,_,_,_,_,

	_,_,t,T,T,T,T,T,_,_,_,_,
	_,_,_,_,_,T,T,T,_,_,_,_,
	_,_,_,_,_,T,T,_,_,_,_,_,
	_,_,_,_,_,T,T,_,_,_,_,_,
	_,L,_,_,_,T,T,_,_,_,_,_,
	L,L,L,L,L,T,T,T,L,L,L,L,
	L,T,T,T,T,T,T,L,T,L,L,_,
	_,L,L,L,L,L,T,L,L,L,L,_,
	_,_,L,L,L,L,T,L,L,L,L,_,
	_,_,_,L,_,L,T,L,L,_,_,_,
	_,_,_,L,L,L,T,L,L,_,_,_,
	_,_,_,L,L,L,L,L,L,_,_,_,
	_,_,_,_,L,L,L,_,_,_,_,_,
	_,_,_,_,L,L,L,_,_,_,_,_,

	_,_,_,_,_,T,_,_,_,_,_,_,
	_,_,_,_,_,T,_,_,_,_,_,_,
	_,_,_,_,_,_,_,_,_,_,_,_,
	_,_,_,L,_,_,_,_,_,_,_,_,
	_,_,_,L,L,_,L,_,L,L,_,_,
	_,L,L,L,L,L,L,_,L,L,L,_,
	_,L,T,L,L,L,L,L,L,L,_,_,
	_,L,L,L,L,L,T,L,L,L,_,_,
	_,_,L,L,L,L,L,L,L,L,_,_,
	_,_,L,L,L,L,T,L,L,L,_,_,
	_,_,_,L,L,L,L,L,L,_,_,_,
	_,_,_,L,L,L,L,L,_,_,_,_,
	_,_,_,_,L,L,L,_,_,_,_,_,
	_,_,_,_,_,L,L,_,_,_,_,_,

	_,_,_,_,_,T,_,_,_,_,_,_,
	_,_,_,_,_,_,_,_,_,_,_,_,
	_,_,_,_,_,_,_,_,_,_,_,_,
	_,_,_,_,_,_,_,_,_,_,_,_,
	_,_,L,_,_,_,_,_,_,_,_,_,
	_,L,L,_,_,L,L,_,L,L,L,_,
	_,L,T,L,L,L,L,L,L,L,_,_,
	_,_,L,_,L,L,T,L,L,L,_,_,
	_,_,L,L,L,L,L,L,L,_,_,_,
	_,_,_,_,L,L,T,T,L,_,_,_,
	_,_,_,_,L,L,L,L,_,_,_,_,
	_,_,_,_,L,L,L,_,_,_,_,_,
	_,_,_,_,_,L,L,_,_,_,_,_,
	_,_,_,_,_,_,_,_,_,_,_,_,

	_,_,_,_,_,T,T,t,_,_,_,_,
	_,_,_,_,_,_,_,_,_,_,_,_,
	_,_,_,_,_,_,_,_,_,_,_,_,
	_,_,_,_,_,_,_,L,_,_,_,_,
	_,_,_,_,L,_,_,L,_,L,_,_,
	_,_,L,L,L,L,L,L,L,L,_,_,
	_,_,L,L,L,L,T,L,L,_,_,_,
	_,_,_,L,L,L,T,L,_,_,_,_,
	_,_,_,_,L,L,L,L,_,_,_,_,
	_,_,_,_,L,L,L,L,_,_,_,_,
	_,_,_,_,_,L,L,_,_,_,_,_,
	_,_,_,_,_,_,_,_,_,_,_,_,
	_,_,_,_,_,_,_,_,_,_,_,_,
	_,_,_,_,_,_,_,_,_,_,_,_,

	_,_,_,_,_,_,t,_,_,_,_,_,
	_,_,_,_,_,_,_,_,_,_,_,_,
	_,_,_,_,_,_,_,_,_,_,_,_,
	_,_,_,L,_,_,_,_,_,_,_,_,
	_,_,_,L,_,_,_,_,_,_,_,_,
	_,_,_,L,L,L,L,L,L,_,_,_,
	_,_,_,L,L,L,T,L,_,_,_,_,
	_,_,_,_,_,L,L,L,_,_,_,_,
	_,_,_,_,_,_,_,_,_,_,_,_,
	_,_,_,_,_,_,_,_,_,_,_,_,
	_,_,_,_,_,_,_,_,_,_,_,_,
	_,_,_,_,_,_,_,_,_,_,_,_,
	_,_,_,_,_,_,_,_,_,_,_,_,
	_,_,_,_,_,_,_,_,_,_,_,_,

	_,_,_,_,_,_,_,_,_,_,_,_,
	_,_,_,_,_,_,_,_,_,_,_,_,
	_,_,_,_,_,_,_,_,_,_,_,_,
	_,_,_,_,_,_,_,_,_,_,_,_,
	_,_,_,_,_,_,L,_,_,_,_,_,
	_,_,_,_,_,L,L,_,_,_,_,_,
	_,_,_,_,_,_,L,_,_,_,_,_,
	_,_,_,_,_,_,_,_,_,_,_,_,
	_,_,_,_,_,_,_,_,_,_,_,_,
	_,_,_,_,_,_,_,_,_,_,_,_,
	_,_,_,_,_,_,_,_,_,_,_,_,
	_,_,_,_,_,_,_,_,_,_,_,_,
	_,_,_,_,_,_,_,_,_,_,_,_,
	_,_,_,_,_,_,_,_,_,_,_,_,

	}
}
